<?xml version="1.0" encoding="utf-8"?>
<!-- This URDF was automatically created by SolidWorks to URDF Exporter! Originally created by Stephen Brawner (brawner@gmail.com) 
     Commit Version: 1.5.1-0-g916b5db  Build Version: 1.5.7152.31018
     For more information, please see http://wiki.ros.org/sw_urdf_exporter -->
<robot
  name="arm">
  <link
    name="base_link">
    <!--visual>
      <origin
        xyz="0 0 0"
        rpy="0 0 0" />
      <geometry>
        <mesh
          filename="package://griper/meshes/base_link.STL" />
      </geometry>
    </visual-->
  </link>

  <link
    name="leftarm_link1">
    <inertial>
      <origin
        xyz="5.55636001264848E-06 0.0288426218219448 -0.0719468523797084"
        rpy="0 0 0" />
      <mass
        value="0.185843840147318" />
      <inertia
        ixx="0.000648795137567167"
        ixy="2.97405201709316E-08"
        ixz="2.74002482408397E-08"
        iyy="0.000733900314751349"
        iyz="-0.000151109528398387"
        izz="0.000491282759255518" />
    </inertial>
    <visual>
      <origin
        xyz="0 0 0"
        rpy="0 0 0" />
      <geometry>
        <mesh
          filename="package://arm_model/meshes/leftarm_link1.obj" />
      </geometry>
      <material
        name="">
        <color
          rgba="0.898039215686275 0.913725490196078 0.925490196078431 1" />
      </material>
    </visual>
    <collision>
      <origin
        xyz="0 0 0"
        rpy="0 0 0" />
      <geometry>
        <mesh
          filename="package://arm_model/meshes/leftarm_link1.STL" />
      </geometry>
    </collision>
  </link>
  <joint
    name="leftarm_joint1"
    type="revolute">
    <origin
      xyz="0 0 0.3"
      rpy="0 0 0" />
    <parent
      link="base_link" />
    <child
      link="leftarm_link1" />
    <axis
      xyz="0 0 1" />
    <limit
      lower="-1.57"
      upper="1.57"
      effort="0"
      velocity="0" />
  </joint>
  <link
    name="leftarm_link2">
    <inertial>
      <origin
        xyz="8.00238142417697E-09 -0.0871819124783481 -0.000487247269088549"
        rpy="0 0 0" />
      <mass
        value="1.90490933692951" />
      <inertia
        ixx="0.0187743359656438"
        ixy="-1.72667623805475E-10"
        ixz="2.36806134467782E-10"
        iyy="0.00310589558857611"
        iyz="-0.000254496269531722"
        izz="0.0186287374840551" />
    </inertial>
    <visual>
      <origin
        xyz="0 0 0"
        rpy="0 0 0" />
      <geometry>
        <mesh
          filename="package://arm_model/meshes/leftarm_link2.obj" />
      </geometry>
      <material
        name="">
        <color
          rgba="0.752941176470588 0.752941176470588 0.752941176470588 1" />
      </material>
    </visual>
    <collision>
      <origin
        xyz="0 0 0"
        rpy="0 0 0" />
      <geometry>
        <mesh
          filename="package://arm_model/meshes/leftarm_link2.STL" />
      </geometry>
    </collision>
  </link>
  <joint
    name="leftarm_joint2"
    type="revolute">
    <origin
      xyz="0 0 0"
      rpy="-1.5708 0 0" />
    <parent
      link="leftarm_link1" />
    <child
      link="leftarm_link2" />
    <axis
      xyz="0 0 1" />
    <limit
      lower="-1.57"
      upper="1.57"
      effort="0"
      velocity="0" />
  </joint>
  <link
    name="leftarm_link3">
    <inertial>
      <origin
        xyz="-0.0155054054014349 0.0176104587173533 -0.0972649243526421"
        rpy="0 0 0" />
      <mass
        value="0.209213306011879" />
      <inertia
        ixx="0.00173915719253396"
        ixy="2.27350480852923E-05"
        ixz="0.000221363794616359"
        iyy="0.0018810977872288"
        iyz="-0.00015929064906947"
        izz="0.000333123310451502" />
    </inertial>
    <visual>
      <origin
        xyz="0 0 0"
        rpy="0 0 0" />
      <geometry>
        <mesh
          filename="package://arm_model/meshes/leftarm_link3.obj" />
      </geometry>
      <material
        name="">
        <color
          rgba="0.898039215686275 0.913725490196078 0.925490196078431 1" />
      </material>
    </visual>
    <collision>
      <origin
        xyz="0 0 0"
        rpy="0 0 0" />
      <geometry>
        <mesh
          filename="package://arm_model/meshes/leftarm_link3.STL" />
      </geometry>
    </collision>
  </link>
  <joint
    name="leftarm_joint3"
    type="revolute">
    <origin
      xyz="0 -0.4495 0"
      rpy="1.5708 0 0" />
    <parent
      link="leftarm_link2" />
    <child
      link="leftarm_link3" />
    <axis
      xyz="0 0 1" />
    <limit
      lower="-1.57"
      upper="1.57"
      effort="0"
      velocity="0" />
  </joint>
  <link
    name="leftarm_link4">
    <inertial>
      <origin
        xyz="0.0110265333983113 -0.0799852039296288 -0.00108071218906549"
        rpy="0 0 0" />
      <mass
        value="1.33690625718003" />
      <inertia
        ixx="0.0167776214945798"
        ixy="0.00198890984901769"
        ixz="2.96057292568186E-05"
        iyy="0.00218457251751038"
        iyz="-0.000118920676489954"
        izz="0.0167428671342608" />
    </inertial>
    <visual>
      <origin
        xyz="0 0 0"
        rpy="0 0 0" />
      <geometry>
        <mesh
          filename="package://arm_model/meshes/leftarm_link4.obj" />
      </geometry>
      <material
        name="">
        <color
          rgba="0.752941176470588 0.752941176470588 0.752941176470588 1" />
      </material>
    </visual>
    <collision>
      <origin
        xyz="0 0 0"
        rpy="0 0 0" />
      <geometry>
        <mesh
          filename="package://arm_model/meshes/leftarm_link4.STL" />
      </geometry>
    </collision>
  </link>
  <joint
    name="leftarm_joint4"
    type="revolute">
    <origin
      xyz="-0.03 0 0"
      rpy="-1.5708 0 0" />
    <parent
      link="leftarm_link3" />
    <child
      link="leftarm_link4" />
    <axis
      xyz="0 0 1" />
    <limit
      lower="-1.57"
      upper="1.57"
      effort="0"
      velocity="0" />
  </joint>
  <link
    name="leftarm_link5">
    <inertial>
      <origin
        xyz="-1.03809204565763E-08 0.0443595329846337 -0.105428960201801"
        rpy="0 0 0" />
      <mass
        value="0.10575077384632" />
      <inertia
        ixx="0.000617136760733635"
        ixy="-3.54168110192346E-11"
        ixz="-6.68780404729048E-11"
        iyy="0.000561067761108561"
        iyz="-0.000173267808268949"
        izz="0.000159582914664926" />
    </inertial>
    <visual>
      <origin
        xyz="0 0 0"
        rpy="0 0 0" />
      <geometry>
        <mesh
          filename="package://arm_model/meshes/leftarm_link5.obj" />
      </geometry>
      <material
        name="">
        <color
          rgba="0.898039215686275 0.913725490196078 0.925490196078431 1" />
      </material>
    </visual>
    <collision>
      <origin
        xyz="0 0 0"
        rpy="0 0 0" />
      <geometry>
        <mesh
          filename="package://arm_model/meshes/leftarm_link5.STL" />
      </geometry>
    </collision>
  </link>
  <joint
    name="leftarm_joint5"
    type="revolute">
    <origin
      xyz="0.03 -0.4495 0"
      rpy="1.5708 0 0" />
    <parent
      link="leftarm_link4" />
    <child
      link="leftarm_link5" />
    <axis
      xyz="0 0 1" />
    <limit
      lower="-1.57"
      upper="1.57"
      effort="0"
      velocity="0" />
  </joint>
  <link
    name="leftarm_link6">
    <inertial>
      <origin
        xyz="0.00111786512590739 -0.00737759119391534 -0.00255095894124485"
        rpy="0 0 0" />
      <mass
        value="2.16214825847123" />
      <inertia
        ixx="0.00602513474729965"
        ixy="-1.78610000917091E-05"
        ixz="0.000134785697607461"
        iyy="0.00509339137287331"
        iyz="5.66252208164899E-05"
        izz="0.00621299091987803" />
    </inertial>
    <visual>
      <origin
        xyz="0 0 0"
        rpy="0 0 3.1416" />
      <geometry>
        <mesh
          filename="package://arm_model/meshes/leftarm_link6_.STL" />
      </geometry>
      <material
        name="">
        <color
          rgba="0.792156862745098 0.819607843137255 0.933333333333333 1" />
      </material>
    </visual>
    <collision>
      <origin
        xyz="0 0 0"
        rpy="0 0 0" />
      <geometry>
        <mesh
          filename="package://arm_model/meshes/leftarm_link6_.STL" />
      </geometry>
    </collision>
  </link>
  <joint
    name="leftarm_joint6"
    type="revolute">
    <origin
      xyz="0 0 0"
      rpy="-1.5708 0 0" />
    <parent
      link="leftarm_link5" />
    <child
      link="leftarm_link6" />
    <axis
      xyz="0 0 1" />
    <limit
      lower="-1.57"
      upper="1.57"
      effort="0"
      velocity="0" />
  </joint>
  <link
    name="leftarm_link7">
    <inertial>
      <origin
        xyz="0.13844 -2.1332E-05 0.014219"
        rpy="0 0 0" />
      <mass
        value="0.47981" />
      <inertia
        ixx="0.00035732"
        ixy="1.4355E-07"
        ixz="0.00012634"
        iyy="0.00050931"
        iyz="-3.9431E-08"
        izz="0.0003531" />
    </inertial>
    <visual>
      <origin
        xyz="0 0 0"
        rpy="03.1416 0 0" />
      <geometry>
        <mesh
          filename="package://arm_model/meshes/leftarm_link7_.STL" />
      </geometry>
      <material
        name="">
        <color
          rgba="0.1 0.1 0.1 1" />
      </material>
    </visual>
    <collision>
      <origin
        xyz="0 0 0"
        rpy="0 0 0" />
      <geometry>
        <mesh
          filename="package://arm_model/meshes/leftarm_link7_.STL" />
      </geometry>
    </collision>
  </link>
  <joint
    name="leftarm_joint7"
    type="revolute">
    <origin
      xyz="0 0 0"
      rpy="1.5708 0 3.1416" />
    <parent
      link="leftarm_link6" />
    <child
      link="leftarm_link7" />
    <axis
      xyz="0 0 1" />
    <limit
      lower="-1.57"
      upper="1.57"
      effort="0"
      velocity="0" />
  </joint>
  <link
    name="griper1">
    <inertial>
      <origin
        xyz="0.016041 0.048076 -4.9981E-05"
        rpy="0 0 0" />
      <mass
        value="0.11514" />
      <inertia
        ixx="0.00014093"
        ixy="-2.1606E-05"
        ixz="-3.1455E-11"
        iyy="7.8491E-05"
        iyz="-8.2644E-11"
        izz="8.535E-05" />
    </inertial>
    <visual>
      <origin
        xyz="0 0 0"
        rpy="0 0 0" />
      <geometry>
        <mesh
          filename="package://arm_model/meshes/griper1.STL" />
      </geometry>
      <material
        name="">
        <color
          rgba="0.89804 0.91765 0.92941 1" />
      </material>
    </visual>
    <collision>
      <origin
        xyz="0 0 0"
        rpy="0 0 0" />
      <geometry>
        <mesh
          filename="package://arm_model/meshes/griper1.STL" />
      </geometry>
    </collision>
  </link>
  <joint
    name="griper_joint1"
    type="revolute">
    <origin
      xyz="0.19797 0.027 0.00015"
      rpy="-3.1416 0 1.5708" />
    <parent
      link="leftarm_link7" />
    <child
      link="griper1" />
    <axis
      xyz="0 0 1" />
    <limit
      lower="0"
      upper="0"
      effort="0"
      velocity="0" />
  </joint>
  <link
    name="griper2">
    <inertial>
      <origin
        xyz="0.016041 0.048076 5.0018E-05"
        rpy="0 0 0" />
      <mass
        value="0.11514" />
      <inertia
        ixx="0.00014093"
        ixy="-2.1606E-05"
        ixz="-3.3253E-11"
        iyy="7.8491E-05"
        iyz="-8.1585E-11"
        izz="8.535E-05" />
    </inertial>
    <visual>
      <origin
        xyz="0 0 0"
        rpy="0 0 0" />
      <geometry>
        <mesh
          filename="package://arm_model/meshes/griper1.STL" />
      </geometry>
      <material
        name="">
        <color
          rgba="0.89804 0.91765 0.92941 1" />
      </material>
    </visual>
    <collision>
      <origin
        xyz="0 0 0"
        rpy="0 0 0" />
      <geometry>
        <mesh
          filename="package://arm_model/meshes/griper1.STL" />
      </geometry>
    </collision>
  </link>
  <joint
    name="griper_joint2"
    type="revolute">
    <origin
      xyz="0.19797 -0.027 0.00015"
      rpy="0 0 -1.5708" />
    <parent
      link="leftarm_link7" />
    <child
      link="griper2" />
    <axis
      xyz="0 0 -1" />
    <limit
      lower="0"
      upper="0"
      effort="0"
      velocity="0" />
  </joint>


</robot>
